
# Exception Handling in Python Functions: A Robust Approach

In Python, functions with exceptions offer a powerful mechanism to manage unexpected situations that may arise during their execution. These situations, often termed errors, can stem from various factors:

- **User Input:** Invalid data provided by the user can lead to errors during processing. For instance, attempting to divide by zero or using incompatible data types for operations.
- **External Factors:** System errors, network issues, or resource limitations can disrupt the function's normal operation.
- **Logical Errors:** Code-related mistakes, like accessing non-existent data or performing invalid calculations, can also trigger errors.

## Throwing Exceptions: Signaling Errors

When a function encounters an unexpected situation, it can throw an exception. This exception object acts as a messenger, encapsulating details about the error, including:

- **Error Type:** This identifies the specific kind of error that occurred, such as `ZeroDivisionError` or `IndexError`.
- **Error Message:** A human-readable description of the error, providing context for debugging purposes.
- **Traceback:** (Optional) An informational stack trace indicating the line of code where the error originated and the call stack that led to the error.

## Catching Exceptions: Graceful Handling

Throwing an exception doesn't necessarily halt the entire program's execution. Python's `try-except` construct provides a structured approach to catch and handle exceptions gracefully:

```python
try:
    # Code that might raise an exception
except ExceptionType:
    # Handle specific exception
else:
    # Code to execute if no exceptions occur
```

## Illustrative Example:

```python
def division(x, y):
    """
    This function demonstrates exception handling for division.
    """
    try:
        result = x / y
    except ZeroDivisionError:
        print("Error: Division by zero is not allowed.")
        return None  # Indicate error by returning None
    except TypeError:
        print("Error: Incompatible data types for division.")
        return None  # Handle incompatible data types
    else:
        print("Result:", result)
        return result  # Return the result if no errors occur

# Example usage
result = division(10, 2)   # Output: Result: 5.0
result = division(10, 0)   # Output: Error: Division by zero is not allowed.
                           #         None
result = division("10", 2)  # Output: Error: Incompatible data types for division.
                            #         None
```

## Key Benefits of Exception Handling:

- **Enhanced Code Robustness:** By gracefully handling exceptions, functions can prevent unexpected program crashes, making the code more reliable.
- **Improved Maintainability:** Separating error handling logic from the core functionality of the function promotes cleaner and easier-to-understand code.
- **Reusable Functions:** Functions don't need to incorporate logic for handling every possible error scenario. Exceptions enable centralized handling, improving code reusability.

## Common Built-in Exceptions:

Python offers a range of built-in exceptions to handle various error conditions:

- `ZeroDivisionError`: Raised when attempting division by zero.
- `TypeError`: Occurs when an operation is attempted with incompatible data types.
- `IndexError`: Thrown when trying to access an element outside the list/array's index range.
- `KeyError`: Raised when accessing a non-existent key in a dictionary.
- `IOError`: Signals issues during file reading or writing operations.

## Custom Exceptions: Tailored Error Handling for Specific Needs

While built-in exceptions cover common scenarios, you can define custom exceptions to cater to specific error conditions within your application. Here's how:

### Create a Class:

```python
class MyCustomError(Exception):
    """
    This class defines a custom exception for specific errors.
    """
    def __init__(self, message):
        # Initialize the exception with a message
        self.message = message
```

### Raise the Exception:

```python
def my_function(data):
    if not isinstance(data, list):
        raise MyCustomError("Error: Data must be a list.")
    # Rest of the function logic
```

## Leveraging the finally Block: Ensuring Essential Actions

The `finally` block (optional) is another crucial component of exception handling. It executes regardless of whether an exception occurs within the `try` block. This is useful for performing actions that must always be carried out, such as:

- Closing opened files: Ensures proper resource management and prevents resource leaks.
- Releasing database connections: Guarantees that database connections are closed even if an exception occurs.
- Cleaning up temporary resources: Ensures that temporary files or other resources are cleaned up after function execution.

### Example:

```python
def write_to_file(data, filename):
    try:
        with open(filename, 'w') as f:
            f.write(data)
    except IOError:
        print("Error: An error occurred while writing to the file.")
    finally:
        # Assuming 'f' is the file object
        if f:
            f.close()  # Close the file even if an exception occurs
```

## Teaching Exception Handling Effectively:

- **Gradual Introduction:** Begin by explaining basic exceptions like `ZeroDivisionError` and how they can disrupt program flow.
- **Interactive Examples:** Use code examples with various exception scenarios and demonstrate how to handle them using `try-except` blocks.
- **Highlight Best Practices:** Emphasize the importance of catching specific exceptions whenever possible for more informative error messages.
- **Introduce Custom Exceptions:** As students gain understanding, introduce custom exceptions to showcase how to handle application-specific errors.
- **Real-world Use Cases:** Discuss practical examples of exception handling in different domains, like file processing, network interactions, or user input validation.
